Entrenant el model...
Traceback (most recent call last):
  File "/home/grau/github-classroom/DCC-UAB/ACproject-15-grup/src/Primer model/controller.py", line 125, in <module>
    main()
  File "/home/grau/github-classroom/DCC-UAB/ACproject-15-grup/src/Primer model/controller.py", line 106, in main
    model, best_params = train_xgboost(bow_train, labels_train)
                         ^^^^^^^^^^^^^^^^^^^^^^^^^^^^^^^^^^^^^^
  File "/home/grau/github-classroom/DCC-UAB/ACproject-15-grup/src/Primer model/train_test.py", line 59, in train_xgboost
    best_params, model = grid_search(X_train, y_train, xgb_model, parameters)
                         ^^^^^^^^^^^^^^^^^^^^^^^^^^^^^^^^^^^^^^^^^^^^^^^^^^^^
  File "/home/grau/github-classroom/DCC-UAB/ACproject-15-grup/src/Primer model/train_test.py", line 19, in grid_search
    grid_search_cv.fit(X_train, y_train)
  File "/home/grau/myenv/lib/python3.12/site-packages/sklearn/base.py", line 1473, in wrapper
    return fit_method(estimator, *args, **kwargs)
           ^^^^^^^^^^^^^^^^^^^^^^^^^^^^^^^^^^^^^^
  File "/home/grau/myenv/lib/python3.12/site-packages/sklearn/model_selection/_search.py", line 1019, in fit
    self._run_search(evaluate_candidates)
  File "/home/grau/myenv/lib/python3.12/site-packages/sklearn/model_selection/_search.py", line 1573, in _run_search
    evaluate_candidates(ParameterGrid(self.param_grid))
  File "/home/grau/myenv/lib/python3.12/site-packages/sklearn/model_selection/_search.py", line 996, in evaluate_candidates
    _warn_or_raise_about_fit_failures(out, self.error_score)
  File "/home/grau/myenv/lib/python3.12/site-packages/sklearn/model_selection/_validation.py", line 529, in _warn_or_raise_about_fit_failures
    raise ValueError(all_fits_failed_message)
ValueError:
All the 3 fits failed.
It is very likely that your model is misconfigured.
You can try to debug the error by setting error_score='raise'.

Below are more details about the failures:
--------------------------------------------------------------------------------
1 fits failed with the following error:
Traceback (most recent call last):
  File "/home/grau/myenv/lib/python3.12/site-packages/sklearn/model_selection/_validation.py", line 888, in _fit_and_score
    estimator.fit(X_train, y_train, **fit_params)
  File "/home/grau/myenv/lib/python3.12/site-packages/xgboost/core.py", line 726, in inner_f
    return func(**kwargs)
           ^^^^^^^^^^^^^^
  File "/home/grau/myenv/lib/python3.12/site-packages/xgboost/sklearn.py", line 1531, in fit
    self._Booster = train(
                    ^^^^^^
  File "/home/grau/myenv/lib/python3.12/site-packages/xgboost/core.py", line 726, in inner_f
    return func(**kwargs)
           ^^^^^^^^^^^^^^
  File "/home/grau/myenv/lib/python3.12/site-packages/xgboost/training.py", line 181, in train
    bst.update(dtrain, iteration=i, fobj=obj)
  File "/home/grau/myenv/lib/python3.12/site-packages/xgboost/core.py", line 2100, in update
    _check_call(
  File "/home/grau/myenv/lib/python3.12/site-packages/xgboost/core.py", line 284, in _check_call
    raise XGBoostError(py_str(_LIB.XGBGetLastError()))
xgboost.core.XGBoostError: [21:09:22] /workspace/src/objective/regression_obj.cu:50: Check failed: info.labels.Size() == preds.Size() (533 vs. 1066) : Invalid shape of labels.
Stack trace:
  [bt] (0) /home/grau/myenv/lib/python3.12/site-packages/xgboost/lib/libxgboost.so(+0x22dcbc) [0x7c017222dcbc]
  [bt] (1) /home/grau/myenv/lib/python3.12/site-packages/xgboost/lib/libxgboost.so(+0xc30292) [0x7c0172c30292]
  [bt] (2) /home/grau/myenv/lib/python3.12/site-packages/xgboost/lib/libxgboost.so(+0xc76a3f) [0x7c0172c76a3f]
  [bt] (3) /home/grau/myenv/lib/python3.12/site-packages/xgboost/lib/libxgboost.so(+0x5cb173) [0x7c01725cb173]
  [bt] (4) /home/grau/myenv/lib/python3.12/site-packages/xgboost/lib/libxgboost.so(XGBoosterUpdateOneIter+0x6f) [0x7c017213752f]
  [bt] (5) /lib/x86_64-linux-gnu/libffi.so.8(+0x7b16) [0x7c018edc0b16]
  [bt] (6) /lib/x86_64-linux-gnu/libffi.so.8(+0x43ef) [0x7c018edbd3ef]
  [bt] (7) /lib/x86_64-linux-gnu/libffi.so.8(ffi_call+0x12e) [0x7c018edc00be]
  [bt] (8) /usr/lib/python3.12/lib-dynload/_ctypes.cpython-312-x86_64-linux-gnu.so(+0xe11c) [0x7c018eb3411c]



--------------------------------------------------------------------------------
1 fits failed with the following error:
Traceback (most recent call last):
  File "/home/grau/myenv/lib/python3.12/site-packages/sklearn/model_selection/_validation.py", line 888, in _fit_and_score
    estimator.fit(X_train, y_train, **fit_params)
  File "/home/grau/myenv/lib/python3.12/site-packages/xgboost/core.py", line 726, in inner_f
    return func(**kwargs)
           ^^^^^^^^^^^^^^
  File "/home/grau/myenv/lib/python3.12/site-packages/xgboost/sklearn.py", line 1531, in fit
    self._Booster = train(
                    ^^^^^^
  File "/home/grau/myenv/lib/python3.12/site-packages/xgboost/core.py", line 726, in inner_f
    return func(**kwargs)
           ^^^^^^^^^^^^^^
  File "/home/grau/myenv/lib/python3.12/site-packages/xgboost/training.py", line 181, in train
    bst.update(dtrain, iteration=i, fobj=obj)
  File "/home/grau/myenv/lib/python3.12/site-packages/xgboost/core.py", line 2100, in update
    _check_call(
  File "/home/grau/myenv/lib/python3.12/site-packages/xgboost/core.py", line 284, in _check_call
    raise XGBoostError(py_str(_LIB.XGBGetLastError()))
xgboost.core.XGBoostError: [21:09:22] /workspace/src/objective/regression_obj.cu:50: Check failed: info.labels.Size() == preds.Size() (533 vs. 1066) : Invalid shape of labels.
Stack trace:
  [bt] (0) /home/grau/myenv/lib/python3.12/site-packages/xgboost/lib/libxgboost.so(+0x22dcbc) [0x7bbb7b02dcbc]
  [bt] (1) /home/grau/myenv/lib/python3.12/site-packages/xgboost/lib/libxgboost.so(+0xc30292) [0x7bbb7ba30292]
  [bt] (2) /home/grau/myenv/lib/python3.12/site-packages/xgboost/lib/libxgboost.so(+0xc76a3f) [0x7bbb7ba76a3f]
  [bt] (3) /home/grau/myenv/lib/python3.12/site-packages/xgboost/lib/libxgboost.so(+0x5cb173) [0x7bbb7b3cb173]
  [bt] (4) /home/grau/myenv/lib/python3.12/site-packages/xgboost/lib/libxgboost.so(XGBoosterUpdateOneIter+0x6f) [0x7bbb7af3752f]
  [bt] (5) /lib/x86_64-linux-gnu/libffi.so.8(+0x7b16) [0x7bbb966cdb16]
  [bt] (6) /lib/x86_64-linux-gnu/libffi.so.8(+0x43ef) [0x7bbb966ca3ef]
  [bt] (7) /lib/x86_64-linux-gnu/libffi.so.8(ffi_call+0x12e) [0x7bbb966cd0be]
  [bt] (8) /usr/lib/python3.12/lib-dynload/_ctypes.cpython-312-x86_64-linux-gnu.so(+0xe11c) [0x7bbb971b911c]



--------------------------------------------------------------------------------
1 fits failed with the following error:
Traceback (most recent call last):
  File "/home/grau/myenv/lib/python3.12/site-packages/sklearn/model_selection/_validation.py", line 888, in _fit_and_score
    estimator.fit(X_train, y_train, **fit_params)
  File "/home/grau/myenv/lib/python3.12/site-packages/xgboost/core.py", line 726, in inner_f
    return func(**kwargs)
           ^^^^^^^^^^^^^^
  File "/home/grau/myenv/lib/python3.12/site-packages/xgboost/sklearn.py", line 1531, in fit
    self._Booster = train(
                    ^^^^^^
  File "/home/grau/myenv/lib/python3.12/site-packages/xgboost/core.py", line 726, in inner_f
    return func(**kwargs)
           ^^^^^^^^^^^^^^
  File "/home/grau/myenv/lib/python3.12/site-packages/xgboost/training.py", line 181, in train
    bst.update(dtrain, iteration=i, fobj=obj)
  File "/home/grau/myenv/lib/python3.12/site-packages/xgboost/core.py", line 2100, in update
    _check_call(
  File "/home/grau/myenv/lib/python3.12/site-packages/xgboost/core.py", line 284, in _check_call
    raise XGBoostError(py_str(_LIB.XGBGetLastError()))
xgboost.core.XGBoostError: [21:09:23] /workspace/src/objective/regression_obj.cu:50: Check failed: info.labels.Size() == preds.Size() (534 vs. 1068) : Invalid shape of labels.
Stack trace:
  [bt] (0) /home/grau/myenv/lib/python3.12/site-packages/xgboost/lib/libxgboost.so(+0x22dcbc) [0x7c7e8222dcbc]
  [bt] (1) /home/grau/myenv/lib/python3.12/site-packages/xgboost/lib/libxgboost.so(+0xc30292) [0x7c7e82c30292]
  [bt] (2) /home/grau/myenv/lib/python3.12/site-packages/xgboost/lib/libxgboost.so(+0xc76a3f) [0x7c7e82c76a3f]
  [bt] (3) /home/grau/myenv/lib/python3.12/site-packages/xgboost/lib/libxgboost.so(+0x5cb173) [0x7c7e825cb173]
  [bt] (4) /home/grau/myenv/lib/python3.12/site-packages/xgboost/lib/libxgboost.so(XGBoosterUpdateOneIter+0x6f) [0x7c7e8213752f]
  [bt] (5) /lib/x86_64-linux-gnu/libffi.so.8(+0x7b16) [0x7c7e9eee1b16]
  [bt] (6) /lib/x86_64-linux-gnu/libffi.so.8(+0x43ef) [0x7c7e9eede3ef]
  [bt] (7) /lib/x86_64-linux-gnu/libffi.so.8(ffi_call+0x12e) [0x7c7e9eee10be]
  [bt] (8) /usr/lib/python3.12/lib-dynload/_ctypes.cpython-312-x86_64-linux-gnu.so(+0xe11c) [0x7c7e9d8bd11c]
